package Com.mar6.exceptionHandling;

import java.util.Scanner;

public class TryCatchFinally 
{
	public static void main(String[] args) throws InterruptedException
	{
		int a = 12;
		int b = 0;
//		Exception e1 = new ArithmeticException();
//		System.out.println(e1);
//		
//		
//		Exception e2 = new ArrayIndexOutOfBoundsException();
//		System.out.println(e2);
//		
		//System.out.println("Main method started...");
		
//		try
//		{
//			int res = a/b;
//			System.out.println(res);
//			//throw new ArithmeticException();
//		}
//		catch(Exception e)
//		{
//			System.err.println("Catch block executed..");
//			System.err.println(e);
//			
//			
//		}
//		
//		System.out.println("Main method ended...");
//	}
		
		
		
		
//		System.out.println("Main method started..");
//		Scanner sc = new Scanner(System.in);
//		
//		System.out.print("Enter the value of x :");
//		int x = sc.nextInt();
//		
//		System.out.print("Enter the value of y :");
//		int y = sc.nextInt();
//		
//		int res = x/y; //[if y value is 0 then program will halt]
//		System.out.println("Result is :"+res);
//		
//		System.out.println("Main method ended..");
//		
//		sc.close();
	}

}
